Workbook

Sheet README
A1: TACTICS CUP — SCORING SHEET
A2: Grade 8 Physical Education · Tactics Lab Unit · 9 lessons across 6 classes and 4 teachers
A4: HOW THIS WORKBOOK WORKS
A5: This workbook tracks the Tactics Cup tournament across all 6 Grade 8 PE classes over 9 lessons. Each class earns points each lesson; the class with the most points at the end of Lesson 9 wins.
A7: TABS IN THIS WORKBOOK
A8: Setup — class names, teacher assignments, and the master configuration. Edit this first.
A9: Score Log — one row per class per lesson (54 rows total). This is where teachers enter scores after each lesson.
A10: Leaderboard — auto-updating ranking of all 6 classes. Visible artifact for students.
A11: Class Detail — drill into any one class's lesson-by-lesson history.
A12: Scoring Criteria — reference doc with award descriptors. Keep this open during scoring.
A14: THE SCORING SYSTEM (per class, per lesson)
A15: Each lesson, each class can earn up to 30 points across four sources:
... A37: • Edit class and teacher names in the Setup tab — they propagate to all other tabs.

Sheet Setup
A1: SETUP — CLASSES & TEACHERS
A2: Edit the class and teacher names below. They will populate throughout the workbook.
A4: Class ID | B4: Class Name | C4: Teacher | D4: # Students
A5: C1 | B5: 8A | C5: Teacher 1 | D5: 28
A6: C2 | B6: 8B | C6: Teacher 1 | D6: 28
A7: C3 | B7: 8C | C7: Teacher 2 | D7: 28
A8: C4 | B8: 8D | C8: Teacher 2 | D8: 28
A9: C5 | B9: 8E | C9: Teacher 3 | D9: 28
A10: C6 | B10: 8F | C10: Teacher 4 | D10: 28
A13: BLOCK SCHEDULE
A14: Block | B14: Lessons | C14: Tactical Problem | D14: Game Pool
A15: Block 1 | B15: L1–L3 | C15: Attack & Defend Territory | D15: Capture the Flag, Basketball, Crossover, Tchoukball, Ultimate, Football, Flag Rugby, Handball, Floor Hockey, Hunger Games, Lacrosse
A16: Block 2 | B16: L4–L6 | C16: Eliminate & Protect | D16: Classic Dodgeball, Pinball/Pin Guard, Benchball, Gaga, Battleship
A17: Block 3 | B17: L7–L9 | C17: Outwit Your Opponent | D17: Pickleball, Badminton, Boxball/Four Square, Table Tennis, Spikeball, Volleyball (2v2)

Sheet Score Log
A1: SCORE LOG — Enter scores here after each lesson
A2: Yellow cells = teacher input. Grey cells = auto-calculated. Total column shows the class's points for that lesson (max 30).
A4: Class | B4: Teacher | C4: Lesson | D4: Block | E4: Games Played | F4: Games Won | G4: Game Pts | H4: Spirit Team | I4: Tactical Team | J4: AP Team 1 | K4: AP Team 2 | L4: Class Total
A5: =Setup!B5 -> 8A | B5: =Setup!C5 -> Teacher 1 | C5: 1 | D5: =IF(C5<=3,"Block 1",IF(C5<=6,"Block 2","Block 3")) -> Block 1 | G5: =MIN(10,IFERROR(E5*2,0)+IFERROR(F5*2,0)) -> 0 | L5: =G5+IF(H5<>"",5,0)+IF(I5<>"",5,0)+IF(J5<>"",5,0)+IF(K5<>"",5,0) -> 0
A6: =Setup!B5 -> 8A | B6: =Setup!C5 -> Teacher 1 | C6: 2 | D6: =IF(C6<=3,"Block 1",IF(C6<=6,"Block 2","Block 3")) -> Block 1 | G6: =MIN(10,IFERROR(E6*2,0)+IFERROR(F6*2,0)) -> 0 | L6: =G6+IF(H6<>"",5,0)+IF(I6<>"",5,0)+IF(J6<>"",5,0)+IF(K6<>"",5,0) -> 0
A7: =Setup!B5 -> 8A | B7: =Setup!C5 -> Teacher 1 | C7: 3 | D7: =IF(C7<=3,"Block 1",IF(C7<=6,"Block 2","Block 3")) -> Block 1 | G7: =MIN(10,IFERROR(E7*2,0)+IFERROR(F7*2,0)) -> 0 | L7: =G7+IF(H7<>"",5,0)+IF(I7<>"",5,0)+IF(J7<>"",5,0)+IF(K7<>"",5,0) -> 0
A8: =Setup!B5 -> 8A | B8: =Setup!C5 -> Teacher 1 | C8: 4 | D8: =IF(C8<=3,"Block 1",IF(C8<=6,"Block 2","Block 3")) -> Block 2 | G8: =MIN(10,IFERROR(E8*2,0)+IFERROR(F8*2,0)) -> 0 | L8: =G8+IF(H8<>"",5,0)+IF(I8<>"",5,0)+IF(J8<>"",5,0)+IF(K8<>"",5,0) -> 0
A9: =Setup!B5 -> 8A | B9: =Setup!C5 -> Teacher 1 | C9: 5 | D9: =IF(C9<=3,"Block 1",IF(C9<=6,"Block 2","Block 3")) -> Block 2 | G9: =MIN(10,IFERROR(E9*2,0)+IFERROR(F9*2,0)) -> 0 | L9: =G9+IF(H9<>"",5,0)+IF(I9<>"",5,0)+IF(J9<>"",5,0)+IF(K9<>"",5,0) -> 0
A10: =Setup!B5 -> 8A | B10: =Setup!C5 -> Teacher 1 | C10: 6 | D10: =IF(C10<=3,"Block 1",IF(C10<=6,"Block 2","Block 3")) -> Block 2 | G10: =MIN(10,IFERROR(E10*2,0)+IFERROR(F10*2,0)) -> 0 | L10: =G10+IF(H10<>"",5,0)+IF(I10<>"",5,0)+IF(J10<>"",5,0)+IF(K10<>"",5,0) -> 0
A11: =Setup!B5 -> 8A | B11: =Setup!C5 -> Teacher 1 | C11: 7 | D11: =IF(C11<=3,"Block 1",IF(C11<=6,"Block 2","Block 3")) -> Block 3 | G11: =MIN(10,IFERROR(E11*2,0)+IFERROR(F11*2,0)) -> 0 | L11: =G11+IF(H11<>"",5,0)+IF(I11<>"",5,0)+IF(J11<>"",5,0)+IF(K11<>"",5,0) -> 0
A12: =Setup!B5 -> 8A | B12: =Setup!C5 -> Teacher 1 | C12: 8 | D12: =IF(C12<=3,"Block 1",IF(C12<=6,"Block 2","Block 3")) -> Block 3 | G12: =MIN(10,IFERROR(E12*2,0)+IFERROR(F12*2,0)) -> 0 | L12: =G12+IF(H12<>"",5,0)+IF(I12<>"",5,0)+IF(J12<>"",5,0)+IF(K12<>"",5,0) -> 0
A13: =Setup!B5 -> 8A | B13: =Setup!C5 -> Teacher 1 | C13: 9 | D13: =IF(C13<=3,"Block 1",IF(C13<=6,"Block 2","Block 3")) -> Block 3 | G13: =MIN(10,IFERROR(E13*2,0)+IFERROR(F13*2,0)) -> 0 | L13: =G13+IF(H13<>"",5,0)+IF(I13<>"",5,0)+IF(J13<>"",5,0)+IF(K13<>"",5,0) -> 0
A14: =Setup!B6 -> 8B | B14: =Setup!C6 -> Teacher 1 | C14: 1 | D14: =IF(C14<=3,"Block 1",IF(C14<=6,"Block 2","Block 3")) -> Block 1 | G14: =MIN(10,IFERROR(E14*2,0)+IFERROR(F14*2,0)) -> 0 | L14: =G14+IF(H14<>"",5,0)+IF(I14<>"",5,0)+IF(J14<>"",5,0)+IF(K14<>"",5,0) -> 0
A15: =Setup!B6 -> 8B | B15: =Setup!C6 -> Teacher 1 | C15: 2 | D15: =IF(C15<=3,"Block 1",IF(C15<=6,"Block 2","Block 3")) -> Block 1 | G15: =MIN(10,IFERROR(E15*2,0)+IFERROR(F15*2,0)) -> 0 | L15: =G15+IF(H15<>"",5,0)+IF(I15<>"",5,0)+IF(J15<>"",5,0)+IF(K15<>"",5,0) -> 0
A16: =Setup!B6 -> 8B | B16: =Setup!C6 -> Teacher 1 | C16: 3 | D16: =IF(C16<=3,"Block 1",IF(C16<=6,"Block 2","Block 3")) -> Block 1 | G16: =MIN(10,IFERROR(E16*2,0)+IFERROR(F16*2,0)) -> 0 | L16: =G16+IF(H16<>"",5,0)+IF(I16<>"",5,0)+IF(J16<>"",5,0)+IF(K16<>"",5,0) -> 0
A17: =Setup!B6 -> 8B | B17: =Setup!C6 -> Teacher 1 | C17: 4 | D17: =IF(C17<=3,"Block 1",IF(C17<=6,"Block 2","Block 3")) -> Block 2 | G17: =MIN(10,IFERROR(E17*2,0)+IFERROR(F17*2,0)) -> 0 | L17: =G17+IF(H17<>"",5,0)+IF(I17<>"",5,0)+IF(J17<>"",5,0)+IF(K17<>"",5,0) -> 0
A18: =Setup!B6 -> 8B | B18: =Setup!C6 -> Teacher 1 | C18: 5 | D18: =IF(C18<=3,"Block 1",IF(C18<=6,"Block 2","Block 3")) -> Block 2 | G18: =MIN(10,IFERROR(E18*2,0)+IFERROR(F18*2,0)) -> 0 | L18: =G18+IF(H18<>"",5,0)+IF(I18<>"",5,0)+IF(J18<>"",5,0)+IF(K18<>"",5,0) -> 0
A19: =Setup!B6 -> 8B | B19: =Setup!C6 -> Teacher 1 | C19: 6 | D19: =IF(C19<=3,"Block 1",IF(C19<=6,"Block 2","Block 3")) -> Block 2 | G19: =MIN(10,IFERROR(E19*2,0)+IFERROR(F19*2,0)) -> 0 | L19: =G19+IF(H19<>"",5,0)+IF(I19<>"",5,0)+IF(J19<>"",5,0)+IF(K19<>"",5,0) -> 0
A20: =Setup!B6 -> 8B | B20: =Setup!C6 -> Teacher 1 | C20: 7 | D20: =IF(C20<=3,"Block 1",IF(C20<=6,"Block 2","Block 3")) -> Block 3 | G20: =MIN(10,IFERROR(E20*2,0)+IFERROR(F20*2,0)) -> 0 | L20: =G20+IF(H20<>"",5,0)+IF(I20<>"",5,0)+IF(J20<>"",5,0)+IF(K20<>"",5,0) -> 0
A21: =Setup!B6 -> 8B | B21: =Setup!C6 -> Teacher 1 | C21: 8 | D21: =IF(C21<=3,"Block 1",IF(C21<=6,"Block 2","Block 3")) -> Block 3 | G21: =MIN(10,IFERROR(E21*2,0)+IFERROR(F21*2,0)) -> 0 | L21: =G21+IF(H21<>"",5,0)+IF(I21<>"",5,0)+IF(J21<>"",5,0)+IF(K21<>"",5,0) -> 0
A22: =Setup!B6 -> 8B | B22: =Setup!C6 -> Teacher 1 | C22: 9 | D22: =IF(C22<=3,"Block 1",IF(C22<=6,"Block 2","Block 3")) -> Block 3 | G22: =MIN(10,IFERROR(E22*2,0)+IFERROR(F22*2,0)) -> 0 | L22: =G22+IF(H22<>"",5,0)+IF(I22<>"",5,0)+IF(J22<>"",5,0)+IF(K22<>"",5,0) -> 0
A23: =Setup!B7 -> 8C | B23: =Setup!C7 -> Teacher 2 | C23: 1 | D23: =IF(C23<=3,"Block 1",IF(C23<=6,"Block 2","Block 3")) -> Block 1 | G23: =MIN(10,IFERROR(E23*2,0)+IFERROR(F23*2,0)) -> 0 | L23: =G23+IF(H23<>"",5,0)+IF(I23<>"",5,0)+IF(J23<>"",5,0)+IF(K23<>"",5,0) -> 0
A24: =Setup!B7 -> 8C | B24: =Setup!C7 -> Teacher 2 | C24: 2 | D24: =IF(C24<=3,"Block 1",IF(C24<=6,"Block 2","Block 3")) -> Block 1 | G24: =MIN(10,IFERROR(E24*2,0)+IFERROR(F24*2,0)) -> 0 | L24: =G24+IF(H24<>"",5,0)+IF(I24<>"",5,0)+IF(J24<>"",5,0)+IF(K24<>"",5,0) -> 0
A25: =Setup!B7 -> 8C | B25: =Setup!C7 -> Teacher 2 | C25: 3 | D25: =IF(C25<=3,"Block 1",IF(C25<=6,"Block 2","Block 3")) -> Block 1 | G25: =MIN(10,IFERROR(E25*2,0)+IFERROR(F25*2,0)) -> 0 | L25: =G25+IF(H25<>"",5,0)+IF(I25<>"",5,0)+IF(J25<>"",5,0)+IF(K25<>"",5,0) -> 0
A26: =Setup!B7 -> 8C | B26: =Setup!C7 -> Teacher 2 | C26: 4 | D26: =IF(C26<=3,"Block 1",IF(C26<=6,"Block 2","Block 3")) -> Block 2 | G26: =MIN(10,IFERROR(E26*2,0)+IFERROR(F26*2,0)) -> 0 | L26: =G26+IF(H26<>"",5,0)+IF(I26<>"",5,0)+IF(J26<>"",5,0)+IF(K26<>"",5,0) -> 0
A27: =Setup!B7 -> 8C | B27: =Setup!C7 -> Teacher 2 | C27: 5 | D27: =IF(C27<=3,"Block 1",IF(C27<=6,"Block 2","Block 3")) -> Block 2 | G27: =MIN(10,IFERROR(E27*2,0)+IFERROR(F27*2,0)) -> 0 | L27: =G27+IF(H27<>"",5,0)+IF(I27<>"",5,0)+IF(J27<>"",5,0)+IF(K27<>"",5,0) -> 0
A28: =Setup!B7 -> 8C | B28: =Setup!C7 -> Teacher 2 | C28: 6 | D28: =IF(C28<=3,"Block 1",IF(C28<=6,"Block 2","Block 3")) -> Block 2 | G28: =MIN(10,IFERROR(E28*2,0)+IFERROR(F28*2,0)) -> 0 | L28: =G28+IF(H28<>"",5,0)+IF(I28<>"",5,0)+IF(J28<>"",5,0)+IF(K28<>"",5,0) -> 0
A29: =Setup!B7 -> 8C | B29: =Setup!C7 -> Teacher 2 | C29: 7 | D29: =IF(C29<=3,"Block 1",IF(C29<=6,"Block 2","Block 3")) -> Block 3 | G29: =MIN(10,IFERROR(E29*2,0)+IFERROR(F29*2,0)) -> 0 | L29: =G29+IF(H29<>"",5,0)+IF(I29<>"",5,0)+IF(J29<>"",5,0)+IF(K29<>"",5,0) -> 0
A30: =Setup!B7 -> 8C | B30: =Setup!C7 -> Teacher 2 | C30: 8 | D30: =IF(C30<=3,"Block 1",IF(C30<=6,"Block 2","Block 3")) -> Block 3 | G30: =MIN(10,IFERROR(E30*2,0)+IFERROR(F30*2,0)) -> 0 | L30: =G30+IF(H30<>"",5,0)+IF(I30<>"",5,0)+IF(J30<>"",5,0)+IF(K30<>"",5,0) -> 0
A31: =Setup!B7 -> 8C | B31: =Setup!C7 -> Teacher 2 | C31: 9 | D31: =IF(C31<=3,"Block 1",IF(C31<=6,"Block 2","Block 3")) -> Block 3 | G31: =MIN(10,IFERROR(E31*2,0)+IFERROR(F31*2,0)) -> 0 | L31: =G31+IF(H31<>"",5,0)+IF(I31<>"",5,0)+IF(J31<>"",5,0)+IF(K31<>"",5,0) -> 0
A32: =Setup!B8 -> 8D | B32: =Setup!C8 -> Teacher 2 | C32: 1 | D32: =IF(C32<=3,"Block 1",IF(C32<=6,"Block 2","Block 3")) -> Block 1 | G32: =MIN(10,IFERROR(E32*2,0)+IFERROR(F32*2,0)) -> 0 | L32: =G32+IF(H32<>"",5,0)+IF(I32<>"",5,0)+IF(J32<>"",5,0)+IF(K32<>"",5,0) -> 0
A33: =Setup!B8 -> 8D | B33: =Setup!C8 -> Teacher 2 | C33: 2 | D33: =IF(C33<=3,"Block 1",IF(C33<=6,"Block 2","Block 3")) -> Block 1 | G33: =MIN(10,IFERROR(E33*2,0)+IFERROR(F33*2,0)) -> 0 | L33: =G33+IF(H33<>"",5,0)+IF(I33<>"",5,0)+IF(J33<>"",5,0)+IF(K33<>"",5,0) -> 0
A34: =Setup!B8 -> 8D | B34: =Setup!C8 -> Teacher 2 | C34: 3 | D34: =IF(C34<=3,"Block 1",IF(C34<=6,"Block 2","Block 3")) -> Block 1 | G34: =MIN(10,IFERROR(E34*2,0)+IFERROR(F34*2,0)) -> 0 | L34: =G34+IF(H34<>"",5,0)+IF(I34<>"",5,0)+IF(J34<>"",5,0)+IF(K34<>"",5,0) -> 0
A35: =Setup!B8 -> 8D | B35: =Setup!C8 -> Teacher 2 | C35: 4 | D35: =IF(C35<=3,"Block 1",IF(C35<=6,"Block 2","Block 3")) -> Block 2 | G35: =MIN(10,IFERROR(E35*2,0)+IFERROR(F35*2,0)) -> 0 | L35: =G35+IF(H35<>"",5,0)+IF(I35<>"",5,0)+IF(J35<>"",5,0)+IF(K35<>"",5,0) -> 0
A36: =Setup!B8 -> 8D | B36: =Setup!C8 -> Teacher 2 | C36: 5 | D36: =IF(C36<=3,"Block 1",IF(C36<=6,"Block 2","Block 3")) -> Block 2 | G36: =MIN(10,IFERROR(E36*2,0)+IFERROR(F36*2,0)) -> 0 | L36: =G36+IF(H36<>"",5,0)+IF(I36<>"",5,0)+IF(J36<>"",5,0)+IF(K36<>"",5,0) -> 0
A37: =Setup!B8 -> 8D | B37: =Setup!C8 -> Teacher 2 | C37: 6 | D37: =IF(C37<=3,"Block 1",IF(C37<=6,"Block 2","Block 3")) -> Block 2 | G37: =MIN(10,IFERROR(E37*2,0)+IFERROR(F37*2,0)) -> 0 | L37: =G37+IF(H37<>"",5,0)+IF(I37<>"",5,0)+IF(J37<>"",5,0)+IF(K37<>"",5,0) -> 0
A38: =Setup!B8 -> 8D | B38: =Setup!C8 -> Teacher 2 | C38: 7 | D38: =IF(C38<=3,"Block 1",IF(C38<=6,"Block 2","Block 3")) -> Block 3 | G38: =MIN(10,IFERROR(E38*2,0)+IFERROR(F38*2,0)) -> 0 | L38: =G38+IF(H38<>"",5,0)+IF(I38<>"",5,0)+IF(J38<>"",5,0)+IF(K38<>"",5,0) -> 0
A39: =Setup!B8 -> 8D | B39: =Setup!C8 -> Teacher 2 | C39: 8 | D39: =IF(C39<=3,"Block 1",IF(C39<=6,"Block 2","Block 3")) -> Block 3 | G39: =MIN(10,IFERROR(E39*2,0)+IFERROR(F39*2,0)) -> 0 | L39: =G39+IF(H39<>"",5,0)+IF(I39<>"",5,0)+IF(J39<>"",5,0)+IF(K39<>"",5,0) -> 0
A40: =Setup!B8 -> 8D | B40: =Setup!C8 -> Teacher 2 | C40: 9 | D40: =IF(C40<=3,"Block 1",IF(C40<=6,"Block 2","Block 3")) -> Block 3 | G40: =MIN(10,IFERROR(E40*2,0)+IFERROR(F40*2,0)) -> 0 | L40: =G40+IF(H40<>"",5,0)+IF(I40<>"",5,0)+IF(J40<>"",5,0)+IF(K40<>"",5,0) -> 0
A41: =Setup!B9 -> 8E | B41: =Setup!C9 -> Teacher 3 | C41: 1 | D41: =IF(C41<=3,"Block 1",IF(C41<=6,"Block 2","Block 3")) -> Block 1 | G41: =MIN(10,IFERROR(E41*2,0)+IFERROR(F41*2,0)) -> 0 | L41: =G41+IF(H41<>"",5,0)+IF(I41<>"",5,0)+IF(J41<>"",5,0)+IF(K41<>"",5,0) -> 0
...

Sheet Leaderboard
A1: 🏆 TACTICS CUP — GRADE-WIDE LEADERBOARD
A2: Live ranking of all 6 classes across all 9 lessons. Updates automatically as scores are logged.
A4: STANDINGS
A5: Rank | B5: Class | C5: Teacher | D5: Total Points | E5: Game Pts | F5: Awards | G5: Lessons Logged | H5: Avg per Lesson
A6: =RANK(D6,$D$6:$D$11) -> 1 | B6: =Setup!B5 -> 8A | C6: =Setup!C5 -> Teacher 1 | D6: =SUM('Score Log'!L5:L13) -> 0 | E6: =SUM('Score Log'!G5:G13) -> 0 | F6: =D6-E6 -> 0 | G6: =COUNTIF('Score Log'!E5:E13,"<>") -> 0 | H6: =IFERROR(D6/G6,0) -> 0
A7: =RANK(D7,$D$6:$D$11) -> 1 | B7: =Setup!B6 -> 8B | C7: =Setup!C6 -> Teacher 1 | D7: =SUM('Score Log'!L14:L22) -> 0 | E7: =SUM('Score Log'!G14:G22) -> 0 | F7: =D7-E7 -> 0 | G7: =COUNTIF('Score Log'!E14:E22,"<>") -> 0 | H7: =IFERROR(D7/G7,0) -> 0
A8: =RANK(D8,$D$6:$D$11) -> 1 | B8: =Setup!B7 -> 8C | C8: =Setup!C7 -> Teacher 2 | D8: =SUM('Score Log'!L23:L31) -> 0 | E8: =SUM('Score Log'!G23:G31) -> 0 | F8: =D8-E8 -> 0 | G8: =COUNTIF('Score Log'!E23:E31,"<>") -> 0 | H8: =IFERROR(D8/G8,0) -> 0
A9: =RANK(D9,$D$6:$D$11) -> 1 | B9: =Setup!B8 -> 8D | C9: =Setup!C8 -> Teacher 2 | D9: =SUM('Score Log'!L32:L40) -> 0 | E9: =SUM('Score Log'!G32:G40) -> 0 | F9: =D9-E9 -> 0 | G9: =COUNTIF('Score Log'!E32:E40,"<>") -> 0 | H9: =IFERROR(D9/G9,0) -> 0
A10: =RANK(D10,$D$6:$D$11) -> 1 | B10: =Setup!B9 -> 8E | C10: =Setup!C9 -> Teacher 3 | D10: =SUM('Score Log'!L41:L49) -> 0 | E10: =SUM('Score Log'!G41:G49) -> 0 | F10: =D10-E10 -> 0 | G10: =COUNTIF('Score Log'!E41:E49,"<>") -> 0 | H10: =IFERROR(D10/G10,0) -> 0
A11: =RANK(D11,$D$6:$D$11) -> 1 | B11: =Setup!B10 -> 8F | C11: =Setup!C10 -> Teacher 4 | D11: =SUM('Score Log'!L50:L58) -> 0 | E11: =SUM('Score Log'!G50:G58) -> 0 | F11: =D11-E11 -> 0 | G11: =COUNTIF('Score Log'!E50:E58,"<>") -> 0 | H11: =IFERROR(D11/G11,0) -> 0
A35: LESSON-BY-LESSON BREAKDOWN
A36: Class | B36: L1 | C36: L2 | D36: L3 | E36: L4 | F36: L5 | G36: L6 | H36: L7 | I36: L8 | J36: L9 | K36: Total
A37: =Setup!B5 -> 8A | B37: ='Score Log'!L5 -> 0 | C37: ='Score Log'!L6 -> 0 | D37: ='Score Log'!L7 -> 0 | E37: ='Score Log'!L8 -> 0 | F37: ='Score Log'!L9 -> 0 | G37: ='Score Log'!L10 -> 0 | H37: ='Score Log'!L11 -> 0 | I37: ='Score Log'!L12 -> 0 | J37: ='Score Log'!L13 -> 0 | K37: =SUM(B37:J37) -> 0
A38: =Setup!B6 -> 8B | B38: ='Score Log'!L14 -> 0 | C38: ='Score Log'!L15 -> 0 | D38: ='Score Log'!L16 -> 0 | E38: ='Score Log'!L17 -> 0 | F38: ='Score Log'!L18 -> 0 | G38: ='Score Log'!L19 -> 0 | H38: ='Score Log'!L20 -> 0 | I38: ='Score Log'!L21 -> 0 | J38: ='Score Log'!L22 -> 0 | K38: =SUM(B38:J38) -> 0
A39: =Setup!B7 -> 8C | B39: ='Score Log'!L23 -> 0 | C39: ='Score Log'!L24 -> 0 | D39: ='Score Log'!L25 -> 0 | E39: ='Score Log'!L26 -> 0 | F39: ='Score Log'!L27 -> 0 | G39: ='Score Log'!L28 -> 0 | H39: ='Score Log'!L29 -> 0 | I39: ='Score Log'!L30 -> 0 | J39: ='Score Log'!L31 -> 0 | K39: =SUM(B39:J39) -> 0
A40: =Setup!B8 -> 8D | B40: ='Score Log'!L32 -> 0 | C40: ='Score Log'!L33 -> 0 | D40: ='Score Log'!L34 -> 0 | E40: ='Score Log'!L35 -> 0 | F40: ='Score Log'!L36 -> 0 | G40: ='Score Log'!L37 -> 0 | H40: ='Score Log'!L38 -> 0 | I40: ='Score Log'!L39 -> 0 | J40: ='Score Log'!L40 -> 0 | K40: =SUM(B40:J40) -> 0
A41: =Setup!B9 -> 8E | B41: ='Score Log'!L41 -> 0 | C41: ='Score Log'!L42 -> 0 | D41: ='Score Log'!L43 -> 0 | E41: ='Score Log'!L44 -> 0 | F41: ='Score Log'!L45 -> 0 | G41: ='Score Log'!L46 -> 0 | H41: ='Score Log'!L47 -> 0 | I41: ='Score Log'!L48 -> 0 | J41: ='Score Log'!L49 -> 0 | K41: =SUM(B41:J41) -> 0
A42: =Setup!B10 -> 8F | B42: ='Score Log'!L50 -> 0 | C42: ='Score Log'!L51 -> 0 | D42: ='Score Log'!L52 -> 0 | E42: ='Score Log'!L53 -> 0 | F42: ='Score Log'!L54 -> 0 | G42: ='Score Log'!L55 -> 0 | H42: ='Score Log'!L56 -> 0 | I42: ='Score Log'!L57 -> 0 | J42: ='Score Log'!L58 -> 0 | K42: =SUM(B42:J42) -> 0

Sheet Class Detail
A1: CLASS DETAIL — Lesson-by-lesson view
A3: Select a class: | B3: 8A | C3: (type a class name from Setup to view that class's detail)
A5: Lesson | B5: Block | C5: Games Played | D5: Games Won | E5: Game Pts | F5: Spirit Team | G5: Tactical Team | H5: AP Team 1 | I5: AP Team 2 | J5: Lesson Total | K5: Running Total
A6: 1 | B6: =IF(A6<=3,"Block 1",IF(A6<=6,"Block 2","Block 3")) -> Block 1 | C6: =IFERROR(SUMIFS('Score Log'!E:E,'Score Log'!A:A,$B$3,'Score Log'!C:C,A6),"") -> 0 | D6: =IFERROR(SUMIFS('Score Log'!F:F,'Score Log'!A:A,$B$3,'Score Log'!C:C,A6),"") -> 0 | E6: =IFERROR(SUMIFS('Score Log'!G:G,'Score Log'!A:A,$B$3,'Score Log'!C:C,A6),"") -> 0 | F6: =IFERROR(INDEX('Score Log'!H:H,MATCH($B$3,'Score Log'!A:A,0)+A6-1),"") -> 0 | G6: =IFERROR(INDEX('Score Log'!I:I,MATCH($B$3,'Score Log'!A:A,0)+A6-1),"") -> 0 | H6: =IFERROR(INDEX('Score Log'!J:J,MATCH($B$3,'Score Log'!A:A,0)+A6-1),"") -> 0 | I6: =IFERROR(INDEX('Score Log'!K:K,MATCH($B$3,'Score Log'!A:A,0)+A6-1),"") -> 0 | J6: =IFERROR(INDEX('Score Log'!L:L,MATCH($B$3,'Score Log'!A:A,0)+A6-1),"") -> 0 | K6: =IFERROR(J6,"") -> 0
A7: 2 | B7: =IF(A7<=3,"Block 1",IF(A7<=6,"Block 2","Block 3")) -> Block 1 | C7: =IFERROR(SUMIFS('Score Log'!E:E,'Score Log'!A:A,$B$3,'Score Log'!C:C,A7),"") -> 0 | D7: =IFERROR(SUMIFS('Score Log'!F:F,'Score Log'!A:A,$B$3,'Score Log'!C:C,A7),"") -> 0 | E7: =IFERROR(SUMIFS('Score Log'!G:G,'Score Log'!A:A,$B$3,'Score Log'!C:C,A7),"") -> 0 | F7: =IFERROR(INDEX('Score Log'!H:H,MATCH($B$3,'Score Log'!A:A,0)+A7-1),"") -> 0 | G7: =IFERROR(INDEX('Score Log'!I:I,MATCH($B$3,'Score Log'!A:A,0)+A7-1),"") -> 0 | H7: =IFERROR(INDEX('Score Log'!J:J,MATCH($B$3,'Score Log'!A:A,0)+A7-1),"") -> 0 | I7: =IFERROR(INDEX('Score Log'!K:K,MATCH($B$3,'Score Log'!A:A,0)+A7-1),"") -> 0 | J7: =IFERROR(INDEX('Score Log'!L:L,MATCH($B$3,'Score Log'!A:A,0)+A7-1),"") -> 0 | K7: =IFERROR(K6+J7,"") -> 0
A8: 3 | B8: =IF(A8<=3,"Block 1",IF(A8<=6,"Block 2","Block 3")) -> Block 1 | C8: =IFERROR(SUMIFS('Score Log'!E:E,'Score Log'!A:A,$B$3,'Score Log'!C:C,A8),"") -> 0 | D8: =IFERROR(SUMIFS('Score Log'!F:F,'Score Log'!A:A,$B$3,'Score Log'!C:C,A8),"") -> 0 | E8: =IFERROR(SUMIFS('Score Log'!G:G,'Score Log'!A:A,$B$3,'Score Log'!C:C,A8),"") -> 0 | F8: =IFERROR(INDEX('Score Log'!H:H,MATCH($B$3,'Score Log'!A:A,0)+A8-1),"") -> 0 | G8: =IFERROR(INDEX('Score Log'!I:I,MATCH($B$3,'Score Log'!A:A,0)+A8-1),"") -> 0 | H8: =IFERROR(INDEX('Score Log'!J:J,MATCH($B$3,'Score Log'!A:A,0)+A8-1),"") -> 0 | I8: =IFERROR(INDEX('Score Log'!K:K,MATCH($B$3,'Score Log'!A:A,0)+A8-1),"") -> 0 | J8: =IFERROR(INDEX('Score Log'!L:L,MATCH($B$3,'Score Log'!A:A,0)+A8-1),"") -> 0 | K8: =IFERROR(K7+J8,"") -> 0
A9: 4 | B9: =IF(A9<=3,"Block 1",IF(A9<=6,"Block 2","Block 3")) -> Block 2 | C9: =IFERROR(SUMIFS('Score Log'!E:E,'Score Log'!A:A,$B$3,'Score Log'!C:C,A9),"") -> 0 | D9: =IFERROR(SUMIFS('Score Log'!F:F,'Score Log'!A:A,$B$3,'Score Log'!C:C,A9),"") -> 0 | E9: =IFERROR(SUMIFS('Score Log'!G:G,'Score Log'!A:A,$B$3,'Score Log'!C:C,A9),"") -> 0 | F9: =IFERROR(INDEX('Score Log'!H:H,MATCH($B$3,'Score Log'!A:A,0)+A9-1),"") -> 0 | G9: =IFERROR(INDEX('Score Log'!I:I,MATCH($B$3,'Score Log'!A:A,0)+A9-1),"") -> 0 | H9: =IFERROR(INDEX('Score Log'!J:J,MATCH($B$3,'Score Log'!A:A,0)+A9-1),"") -> 0 | I9: =IFERROR(INDEX('Score Log'!K:K,MATCH($B$3,'Score Log'!A:A,0)+A9-1),"") -> 0 | J9: =IFERROR(INDEX('Score Log'!L:L,MATCH($B$3,'Score Log'!A:A,0)+A9-1),"") -> 0 | K9: =IFERROR(K8+J9,"") -> 0
A10: 5 | B10: =IF(A10<=3,"Block 1",IF(A10<=6,"Block 2","Block 3")) -> Block 2 | C10: =IFERROR(SUMIFS('Score Log'!E:E,'Score Log'!A:A,$B$3,'Score Log'!C:C,A10),"") -> 0 | D10: =IFERROR(SUMIFS('Score Log'!F:F,'Score Log'!A:A,$B$3,'Score Log'!C:C,A10),"") -> 0 | E10: =IFERROR(SUMIFS('Score Log'!G:G,'Score Log'!A:A,$B$3,'Score Log'!C:C,A10),"") -> 0 | F10: =IFERROR(INDEX('Score Log'!H:H,MATCH($B$3,'Score Log'!A:A,0)+A10-1),"") -> 0 | G10: =IFERROR(INDEX('Score Log'!I:I,MATCH($B$3,'Score Log'!A:A,0)+A10-1),"") -> 0 | H10: =IFERROR(INDEX('Score Log'!J:J,MATCH($B$3,'Score Log'!A:A,0)+A10-1),"") -> 0 | I10: =IFERROR(INDEX('Score Log'!K:K,MATCH($B$3,'Score Log'!A:A,0)+A10-1),"") -> 0 | J10: =IFERROR(INDEX('Score Log'!L:L,MATCH($B$3,'Score Log'!A:A,0)+A10-1),"") -> 0 | K10: =IFERROR(K9+J10,"") -> 0
A11: 6 | B11: =IF(A11<=3,"Block 1",IF(A11<=6,"Block 2","Block 3")) -> Block 2 | C11: =IFERROR(SUMIFS('Score Log'!E:E,'Score Log'!A:A,$B$3,'Score Log'!C:C,A11),"") -> 0 | D11: =IFERROR(SUMIFS('Score Log'!F:F,'Score Log'!A:A,$B$3,'Score Log'!C:C,A11),"") -> 0 | E11: =IFERROR(SUMIFS('Score Log'!G:G,'Score Log'!A:A,$B$3,'Score Log'!C:C,A11),"") -> 0 | F11: =IFERROR(INDEX('Score Log'!H:H,MATCH($B$3,'Score Log'!A:A,0)+A11-1),"") -> 0 | G11: =IFERROR(INDEX('Score Log'!I:I,MATCH($B$3,'Score Log'!A:A,0)+A11-1),"") -> 0 | H11: =IFERROR(INDEX('Score Log'!J:J,MATCH($B$3,'Score Log'!A:A,0)+A11-1),"") -> 0 | I11: =IFERROR(INDEX('Score Log'!K:K,MATCH($B$3,'Score Log'!A:A,0)+A11-1),"") -> 0 | J11: =IFERROR(INDEX('Score Log'!L:L,MATCH($B$3,'Score Log'!A:A,0)+A11-1),"") -> 0 | K11: =IFERROR(K10+J11,"") -> 0
A12: 7 | B12: =IF(A12<=3,"Block 1",IF(A12<=6,"Block 2","Block 3")) -> Block 3 | C12: =IFERROR(SUMIFS('Score Log'!E:E,'Score Log'!A:A,$B$3,'Score Log'!C:C,A12),"") -> 0 | D12: =IFERROR(SUMIFS('Score Log'!F:F,'Score Log'!A:A,$B$3,'Score Log'!C:C,A12),"") -> 0 | E12: =IFERROR(SUMIFS('Score Log'!G:G,'Score Log'!A:A,$B$3,'Score Log'!C:C,A12),"") -> 0 | F12: =IFERROR(INDEX('Score Log'!H:H,MATCH($B$3,'Score Log'!A:A,0)+A12-1),"") -> 0 | G12: =IFERROR(INDEX('Score Log'!I:I,MATCH($B$3,'Score Log'!A:A,0)+A12-1),"") -> 0 | H12: =IFERROR(INDEX('Score Log'!J:J,MATCH($B$3,'Score Log'!A:A,0)+A12-1),"") -> 0 | I12: =IFERROR(INDEX('Score Log'!K:K,MATCH($B$3,'Score Log'!A:A,0)+A12-1),"") -> 0 | J12: =IFERROR(INDEX('Score Log'!L:L,MATCH($B$3,'Score Log'!A:A,0)+A12-1),"") -> 0 | K12: =IFERROR(K11+J12,"") -> 0
A13: 8 | B13: =IF(A13<=3,"Block 1",IF(A13<=6,"Block 2","Block 3")) -> Block 3 | C13: =IFERROR(SUMIFS('Score Log'!E:E,'Score Log'!A:A,$B$3,'Score Log'!C:C,A13),"") -> 0 | D13: =IFERROR(SUMIFS('Score Log'!F:F,'Score Log'!A:A,$B$3,'Score Log'!C:C,A13),"") -> 0 | E13: =IFERROR(SUMIFS('Score Log'!G:G,'Score Log'!A:A,$B$3,'Score Log'!C:C,A13),"") -> 0 | F13: =IFERROR(INDEX('Score Log'!H:H,MATCH($B$3,'Score Log'!A:A,0)+A13-1),"") -> 0 | G13: =IFERROR(INDEX('Score Log'!I:I,MATCH($B$3,'Score Log'!A:A,0)+A13-1),"") -> 0 | H13: =IFERROR(INDEX('Score Log'!J:J,MATCH($B$3,'Score Log'!A:A,0)+A13-1),"") -> 0 | I13: =IFERROR(INDEX('Score Log'!K:K,MATCH($B$3,'Score Log'!A:A,0)+A13-1),"") -> 0 | J13: =IFERROR(INDEX('Score Log'!L:L,MATCH($B$3,'Score Log'!A:A,0)+A13-1),"") -> 0 | K13: =IFERROR(K12+J13,"") -> 0
A14: 9 | B14: =IF(A14<=3,"Block 1",IF(A14<=6,"Block 2","Block 3")) -> Block 3 | C14: =IFERROR(SUMIFS('Score Log'!E:E,'Score Log'!A:A,$B$3,'Score Log'!C:C,A14),"") -> 0 | D14: =IFERROR(SUMIFS('Score Log'!F:F,'Score Log'!A:A,$B$3,'Score Log'!C:C,A14),"") -> 0 | E14: =IFERROR(SUMIFS('Score Log'!G:G,'Score Log'!A:A,$B$3,'Score Log'!C:C,A14),"") -> 0 | F14: =IFERROR(INDEX('Score Log'!H:H,MATCH($B$3,'Score Log'!A:A,0)+A14-1),"") -> 0 | G14: =IFERROR(INDEX('Score Log'!I:I,MATCH($B$3,'Score Log'!A:A,0)+A14-1),"") -> 0 | H14: =IFERROR(INDEX('Score Log'!J:J,MATCH($B$3,'Score Log'!A:A,0)+A14-1),"") -> 0 | I14: =IFERROR(INDEX('Score Log'!K:K,MATCH($B$3,'Score Log'!A:A,0)+A14-1),"") -> 0 | J14: =IFERROR(INDEX('Score Log'!L:L,MATCH($B$3,'Score Log'!A:A,0)+A14-1),"") -> 0 | K14: =IFERROR(K13+J14,"") -> 0

Sheet Scoring Criteria
A1: SCORING CRITERIA — keep this open during scoring
A3: GAME POINTS (max 10)
A4: How it's calculated | B4: Formula | C4: 2 points per game played + 2 points per game won within the class, capped at 10 points per lesson.
A6: SPIRIT AWARD (5 pts)
A7: Who | B7: 1 per class per lesson | C7: Given by the class's teacher to one playing team from that class.
A8: Awarded for | C8: The team that best demonstrated: encouraging teammates and opponents, including quieter or less-skilled players, fair play and respect for rules, and lifting the energy of the playing space.
A9: Tip for teachers | C9: Look for moments rather than overall vibe — one team that visibly included a struggling teammate beats a team that was just generally pleasant.
A11: TACTICAL AWARD (5 pts)
A12: Who | B12: 1 per class per lesson | C12: Given by the class's teacher to one playing team from that class.
A13: Awarded for | C13: The team that best demonstrated: executing a tactic from a Card or their Wall Planner, inventing or refining a tactic during play, articulating tactics aloud or coaching teammates, adapting tactics when opponents adjusted.
A14: Tip for teachers | C14: Listen for tactical language — "let's overload the left" beats silent execution. Invention and articulation are the rare signals.
A16: AP AWARDS (5 pts each × 2)
A17: Who | B17: 2 per class per lesson | C17: Given by the class's teacher to two playing teams from that class.
A18: Awarded for | C18: The two teams that best demonstrated: full engagement throughout the lesson (no opt-outs, no time-outs), visible effort across all game time, and active involvement in Wall Planner discussions and warm-up.
A19: Tip for teachers | C19: Reward the teams whose energy you'd want bottled. If only one team really earned it that lesson, leave AP Team 2 blank — don't give a second award by default.
A21: CONSISTENCY RULES (read before scoring)
A22: #1 | B22: Each teacher has the same fixed budget every lesson: 1 Spirit + 1 Tactical + 2 AP awards. Scarcity ensures consistency between teachers.
A23: #2 | B23: Awards go to playing teams within the class — not individual students, not the class as a whole.
A24: #3 | B24: The points belong to the class. If a team wins the Spirit Award, the class total gets +5.
A25: #4 | B25: In parallel-class lessons, teachers position themselves to observe their own class's teams. You're scoring your own students, not the whole gym.
A26: #5 | B26: If you didn't observe enough of your own class to award something, leave that award blank. The class doesn't get points for an unobserved lesson but isn't penalised either.
A27: #6 | B27: Game points are formula-based — no teacher judgment. Just count games played and games won.
